Workbook

Sheet Summary
A1: Maritime Traffic Analytics - North Sea & English Channel
A2: Snapshot taken 2026-10-11 08:17 UTC. Source: live AIS feed (AISStream), cleaned by run_all.py.
A4: Metric | B4: Value | C4: Note
A5: Ships in the snapshot (after cleaning) | B5: 6877
A6: Under way, speed 0.5 kn or more (%) | B6: 0.168
A7: Idle: stationary but status says under way (%) | B7: 0.293
A8: At anchor (%) | B8: 0.101
A9: At berth / moored (%) | B9: 0.439
A10: Ships inside a port hub's radius | B10: 3233
A11: Ships waiting at anchor near a hub | B11: 275
A12: Dark-fleet flagged (%) | B12: 0.0795
A13: Vessel type unknown (%) | B13: 0.032
A14: With an IMO number (%) | B14: 0.265
A15: IMO passes checksum (%) | B15: 0.255
A16: Destination usable (%) | B16: 0.79
... A19: Median speed of moving ships (kn) | B19: 7.4
A20: Busiest hub (ships in radius) | B20: Rotterdam
A21: Hub with most ships waiting at anchor | B21: Rotterdam
A23: Live check from the Clean_Data sheet (formula, recalculates):
A24: Ships in Clean_Data | B24: =COUNTA(Clean_Data!A2:A6878)
A25: Share moving | B25: =COUNTIF(Clean_Data!K:K,"moving")/B24
A27: Sheets
A28: Hub_Congestion | B28: Ships waiting at anchor near each hub, with green/yellow/red levels (relative to the other hubs)
A29: Fleet_Mix | B29: Live pivot (COUNTIFS on Clean_Data): vessel type x status
A30: Flags / Routes | B30: Top flag states; most common departure -> destination voyages
A31: Data_Quality | B31: Every cleaning rule with the number of rows it touched, and field completeness
A32: Assumptions | B32: Blue cells are inputs with sources. Change one and Estimates recalculates
A33: Estimates | B33: Fuel, CO2 and cost of ships waiting at anchor: ESTIMATES, low / central / high
A34: Clean_Data | B34: The cleaned dataset

Sheet Hub_Congestion
A1: hub | B1: zone | C1: ships_in_radius | D1: at_anchor | E1: idle | F1: at_berth | G1: moving | H1: waiting_broad | I1: avg_speed_moving_kn | J1: pct_at_anchor | K1: level_waiting | L1: level_waiting_broad
A2: Rotterdam | B2: Benelux coast | C2: 1079 | D2: 71 | E2: 279 | F2: 644 | G2: 85 | H2: 350 | I2: 7.6 | J2: 6.6 | K2: red | L2: red
A3: Amsterdam | B3: Benelux coast | C3: 724 | D3: 66 | E3: 328 | F3: 258 | G3: 72 | H3: 394 | I3: 4.7 | J3: 9.1 | K3: red | L3: red
A4: Antwerp | B4: Benelux coast | C4: 378 | D4: 31 | E4: 85 | F4: 199 | G4: 63 | H4: 116 | I4: 6.6 | J4: 8.2 | K4: red | L4: red
A5: Le Havre | B5: Dover Strait & Channel | C5: 93 | D5: 22 | E5: 16 | F5: 30 | G5: 25 | H5: 38 | I5: 8.2 | J5: 23.7 | K5: red | L5: red
A6: IJmuiden | B6: Benelux coast | C6: 144 | D6: 14 | E6: 41 | F6: 82 | G6: 7 | H6: 55 | I6: 4.9 | J6: 9.7 | K6: red | L6: red
A7: Terneuzen | B7: Benelux coast | C7: 132 | D7: 10 | E7: 30 | F7: 70 | G7: 22 | H7: 40 | I7: 6.3 | J7: 7.6 | K7: red | L7: red
A8: Vlissingen | B8: Benelux coast | C8: 125 | D8: 10 | E8: 41 | F8: 62 | G8: 12 | H8: 51 | I8: 8 | J8: 8 | K8: red | L8: red
A9: Bremerhaven | B9: German Bight & Ems | C9: 104 | D9: 9 | E9: 21 | F9: 65 | G9: 9 | H9: 30 | I9: 6.5 | J9: 8.7 | K9: yellow | L9: yellow
A10: Emden | B10: German Bight & Ems | C10: 57 | D10: 8 | E10: 15 | F10: 26 | G10: 8 | H10: 23 | I10: 7.3 | J10: 14 | K10: yellow | L10: yellow
A11: Wilhelmshaven | B11: German Bight & Ems | C11: 66 | D11: 7 | E11: 14 | F11: 45 | G11: 0 | H11: 21 | J11: 10.6 | K11: yellow | L11: yellow
A12: Eemshaven | B12: German Bight & Ems | C12: 103 | D12: 6 | E12: 31 | F12: 60 | G12: 6 | H12: 37 | I12: 5.5 | J12: 5.8 | K12: yellow | L12: yellow
A13: Zeebrugge | B13: Benelux coast | C13: 57 | D13: 6 | E13: 8 | F13: 34 | G13: 9 | H13: 14 | I13: 9.8 | J13: 10.5 | K13: yellow | L13: yellow
A14: Felixstowe | B14: UK east coast & Thames | C14: 34 | D14: 6 | E14: 2 | F14: 21 | G14: 5 | H14: 8 | I14: 7.1 | J14: 17.6 | K14: yellow | L14: green
A15: Southampton | B15: Dover Strait & Channel | C15: 57 | D15: 5 | E15: 12 | F15: 31 | G15: 9 | H15: 17 | I15: 11.8 | J15: 8.8 | K15: green | L15: yellow
A16: Thames (London Gateway) | B16: UK east coast & Thames | C16: 49 | D16: 3 | E16: 8 | F16: 30 | G16: 8 | H16: 11 | I16: 8.2 | J16: 6.1 | K16: green | L16: green
A17: Immingham (Humber) | B17: UK east coast & Thames | C17: 23 | D17: 1 | E17: 3 | F17: 16 | G17: 3 | H17: 4 | I17: 8.2 | J17: 4.3 | K17: green | L17: green
A18: Dover | B18: Dover Strait & Channel | C18: 5 | D18: 0 | E18: 1 | F18: 0 | G18: 4 | H18: 1 | I18: 14.6 | J18: 0 | K18: green | L18: green
A19: Calais | B19: Dover Strait & Channel | C19: 3 | D19: 0 | E19: 0 | F19: 0 | G19: 3 | H19: 0 | I19: 4.6 | J19: 0 | K19: green | L19: green
A20: Dunkirk | B20: Dover Strait & Channel | C20: 0 | D20: 0 | E20: 0 | F20: 0 | G20: 0 | H20: 0 | K20: green | L20: green
A22: Levels are relative: the lowest third of hubs is green, the middle third yellow, the top third red. They are not an industry standard.

Sheet Fleet_Mix
A1: Vessel type x status (live COUNTIFS on Clean_Data)
A3: vessel_type | B3: at_anchor | C3: at_berth | D3: idle | E3: moving | F3: other | G3: total | H3: share
A4: other | B4: =COUNTIFS(Clean_Data!$D:$D,$A4,Clean_Data!$K:$K,B$3) | C4: =COUNTIFS(Clean_Data!$D:$D,$A4,Clean_Data!$K:$K,C$3) | D4: =COUNTIFS(Clean_Data!$D:$D,$A4,Clean_Data!$K:$K,D$3) | E4: =COUNTIFS(Clean_Data!$D:$D,$A4,Clean_Data!$K:$K,E$3) | F4: =COUNTIFS(Clean_Data!$D:$D,$A4,Clean_Data!$K:$K,F$3) | G4: =SUM(B4:F4) | H4: =G4/G$13
A5: cargo | B5: =COUNTIFS(Clean_Data!$D:$D,$A5,Clean_Data!$K:$K,B$3) | C5: =COUNTIFS(Clean_Data!$D:$D,$A5,Clean_Data!$K:$K,C$3) | D5: =COUNTIFS(Clean_Data!$D:$D,$A5,Clean_Data!$K:$K,D$3) | E5: =COUNTIFS(Clean_Data!$D:$D,$A5,Clean_Data!$K:$K,E$3) | F5: =COUNTIFS(Clean_Data!$D:$D,$A5,Clean_Data!$K:$K,F$3) | G5: =SUM(B5:F5) | H5: =G5/G$13
A6: passenger | B6: =COUNTIFS(Clean_Data!$D:$D,$A6,Clean_Data!$K:$K,B$3) | C6: =COUNTIFS(Clean_Data!$D:$D,$A6,Clean_Data!$K:$K,C$3) | D6: =COUNTIFS(Clean_Data!$D:$D,$A6,Clean_Data!$K:$K,D$3) | E6: =COUNTIFS(Clean_Data!$D:$D,$A6,Clean_Data!$K:$K,E$3) | F6: =COUNTIFS(Clean_Data!$D:$D,$A6,Clean_Data!$K:$K,F$3) | G6: =SUM(B6:F6) | H6: =G6/G$13
A7: tanker | B7: =COUNTIFS(Clean_Data!$D:$D,$A7,Clean_Data!$K:$K,B$3) | C7: =COUNTIFS(Clean_Data!$D:$D,$A7,Clean_Data!$K:$K,C$3) | D7: =COUNTIFS(Clean_Data!$D:$D,$A7,Clean_Data!$K:$K,D$3) | E7: =COUNTIFS(Clean_Data!$D:$D,$A7,Clean_Data!$K:$K,E$3) | F7: =COUNTIFS(Clean_Data!$D:$D,$A7,Clean_Data!$K:$K,F$3) | G7: =SUM(B7:F7) | H7: =G7/G$13
A8: pleasure | B8: =COUNTIFS(Clean_Data!$D:$D,$A8,Clean_Data!$K:$K,B$3) | C8: =COUNTIFS(Clean_Data!$D:$D,$A8,Clean_Data!$K:$K,C$3) | D8: =COUNTIFS(Clean_Data!$D:$D,$A8,Clean_Data!$K:$K,D$3) | E8: =COUNTIFS(Clean_Data!$D:$D,$A8,Clean_Data!$K:$K,E$3) | F8: =COUNTIFS(Clean_Data!$D:$D,$A8,Clean_Data!$K:$K,F$3) | G8: =SUM(B8:F8) | H8: =G8/G$13
A9: tug | B9: =COUNTIFS(Clean_Data!$D:$D,$A9,Clean_Data!$K:$K,B$3) | C9: =COUNTIFS(Clean_Data!$D:$D,$A9,Clean_Data!$K:$K,C$3) | D9: =COUNTIFS(Clean_Data!$D:$D,$A9,Clean_Data!$K:$K,D$3) | E9: =COUNTIFS(Clean_Data!$D:$D,$A9,Clean_Data!$K:$K,E$3) | F9: =COUNTIFS(Clean_Data!$D:$D,$A9,Clean_Data!$K:$K,F$3) | G9: =SUM(B9:F9) | H9: =G9/G$13
A10: fishing | B10: =COUNTIFS(Clean_Data!$D:$D,$A10,Clean_Data!$K:$K,B$3) | C10: =COUNTIFS(Clean_Data!$D:$D,$A10,Clean_Data!$K:$K,C$3) | D10: =COUNTIFS(Clean_Data!$D:$D,$A10,Clean_Data!$K:$K,D$3) | E10: =COUNTIFS(Clean_Data!$D:$D,$A10,Clean_Data!$K:$K,E$3) | F10: =COUNTIFS(Clean_Data!$D:$D,$A10,Clean_Data!$K:$K,F$3) | G10: =SUM(B10:F10) | H10: =G10/G$13
A11: unknown | B11: =COUNTIFS(Clean_Data!$D:$D,$A11,Clean_Data!$K:$K,B$3) | C11: =COUNTIFS(Clean_Data!$D:$D,$A11,Clean_Data!$K:$K,C$3) | D11: =COUNTIFS(Clean_Data!$D:$D,$A11,Clean_Data!$K:$K,D$3) | E11: =COUNTIFS(Clean_Data!$D:$D,$A11,Clean_Data!$K:$K,E$3) | F11: =COUNTIFS(Clean_Data!$D:$D,$A11,Clean_Data!$K:$K,F$3) | G11: =SUM(B11:F11) | H11: =G11/G$13
A12: official | B12: =COUNTIFS(Clean_Data!$D:$D,$A12,Clean_Data!$K:$K,B$3) | C12: =COUNTIFS(Clean_Data!$D:$D,$A12,Clean_Data!$K:$K,C$3) | D12: =COUNTIFS(Clean_Data!$D:$D,$A12,Clean_Data!$K:$K,D$3) | E12: =COUNTIFS(Clean_Data!$D:$D,$A12,Clean_Data!$K:$K,E$3) | F12: =COUNTIFS(Clean_Data!$D:$D,$A12,Clean_Data!$K:$K,F$3) | G12: =SUM(B12:F12) | H12: =G12/G$13
A13: Total | B13: =SUM(B4:B12) | C13: =SUM(C4:C12) | D13: =SUM(D4:D12) | E13: =SUM(E4:E12) | F13: =SUM(F4:F12) | G13: =SUM(G4:G12)
A15: Type profile (computed in Python)
A16: vessel_type | B16: ships | C16: share_pct | D16: pct_moving | E16: avg_speed_moving_kn | F16: pct_dark
A17: other | B17: 1733 | C17: 25.2 | D17: 11.9 | E17: 7.7 | F17: 0
A18: cargo | B18: 1723 | C18: 25.1 | D18: 21.8 | E18: 8.3 | F18: 0
A19: passenger | B19: 964 | C19: 14 | D19: 14 | E19: 5.7 | F19: 0
A20: tanker | B20: 887 | C20: 12.9 | D20: 29.2 | E20: 7.9 | F20: 0
A21: pleasure | B21: 438 | C21: 6.4 | D21: 2.3 | E21: 5.2 | F21: 0
A22: tug | B22: 419 | C22: 6.1 | D22: 8.6 | E22: 5.9 | F22: 0
A23: fishing | B23: 312 | C23: 4.5 | D23: 8 | E23: 5.1 | F23: 0
A24: unknown | B24: 221 | C24: 3.2 | D24: 36.7 | E24: 7.3 | F24: 0
A25: official | B25: 180 | C25: 2.6 | D25: 13.3 | E25: 8 | F25: 0

Sheet Flags
A1: flag | B1: ships | C1: share_pct
A2: Netherlands | B2: 4235 | C2: 61.6
A3: Germany | B3: 648 | C3: 9.4
A4: Belgium | B4: 451 | C4: 6.6
A5: United Kingdom | B5: 317 | C5: 4.6
A6: France | B6: 182 | C6: 2.6
A7: Portugal | B7: 97 | C7: 1.4
A8: Switzerland | B8: 93 | C8: 1.4
A9: Malta | B9: 88 | C9: 1.3
A10: Liberia | B10: 77 | C10: 1.1
A11: Cyprus | B11: 76 | C11: 1.1
A12: Panama | B12: 70 | C12: 1
A13: Denmark | B13: 62 | C13: 0.9
... A16: Luxembourg | B16: 49 | C16: 0.7

Sheet Segments
A1: segment | B1: ships | C1: pct_under_way | D1: pct_idle | E1: pct_at_berth | F1: pct_at_anchor | G1: waiting_near_hubs | H1: avg_speed_under_way_kn | I1: share_pct
A2: Cargo & tanker | B2: 2610 | C2: 24.3 | D2: 17.4 | E2: 51.1 | F2: 7.3 | G2: 73 | H2: 8.1 | I2: 38
A3: Other & unknown | B3: 2134 | C3: 14.6 | D3: 28.4 | E3: 45.1 | F3: 11.9 | G3: 102 | H3: 7.6 | I3: 31
A4: Passenger | B4: 964 | C4: 14 | D4: 47.5 | E4: 26.9 | F4: 11.6 | G4: 51 | H4: 5.7 | I4: 14
A5: Pleasure & fishing | B5: 750 | C5: 4.7 | D5: 44.5 | E5: 39.3 | F5: 11.5 | G5: 27 | H5: 5.1 | I5: 10.9
A6: Tug | B6: 419 | C6: 8.6 | D6: 38.7 | E6: 40.8 | F6: 11.9 | G6: 22 | H6: 5.9 | I6: 6.1

Sheet Routes
A1: departure_port | B1: destination | C1: ships | D1: avg_speed_kn
A2: Antwerpen | B2: Antwerp | C2: 23 | D2: 2.2
A3: Europoort | B3: Rotterdam | C3: 20 | D3: 2.1
A4: Vlaardingen | B4: Rotterdam | C4: 18 | D4: 1.1
A5: Maassluis | B5: Rotterdam | C5: 17 | D5: 1.9
A6: Amsterdam | B6: Amsterdam | C6: 11 | D6: 2.1
A7: Hoek Van Holland | B7: Rotterdam | C7: 11 | D7: 3.4
A8: Schiedam | B8: Rotterdam | C8: 11 | D8: 3.5
A9: Zaandam | B9: Amsterdam | C9: 10 | D9: 1.2
A10: Rotterdam | B10: Rotterdam | C10: 9 | D10: 3.4
A11: Antwerpen | B11: Amsterdam | C11: 8 | D11: 6.4
A12: Zaandam | B12: Rotterdam | C12: 8 | D12: 5.9
A13: Bremerhaven | B13: Bremerhaven | C13: 6 | D13: 0
... A16: Antwerpen | B16: Rotterdam | C16: 4 | D16: 6.5
A18: Departure ports are detected live (ship leaves a known port while the backend is watching); destinations are typed by captains.

Sheet Data_Quality
A1: rule | B1: rows_affected | C1: action
A2: Raw rows received | B2: 8881 | C2: -
A3: Missing MMSI (cannot identify the ship) | B3: 0 | C3: dropped
A4: Duplicate MMSI (same ship twice) | B4: 0 | C4: dropped, kept the most recent report
A5: Missing or impossible position | B5: 0 | C5: dropped
A6: Position outside the tracked box | B6: 0 | C6: dropped
A7: Speed = 102.3 kn (AIS 'not available' code) | B7: 17 | C7: set to missing
A8: Negative speed | B8: 0 | C8: set to missing
A9: Implausible speed (> 40 kn) | B9: 14 | C9: set to missing
A10: Vessel type missing | B10: 1035 | C10: labelled 'unknown' (kept)
A11: Ship name missing or 'Unknown' | B11: 423 | C11: name set to missing (kept)
A12: Flag state missing (MMSI country code not recognised) | B12: 34 | C12: labelled 'Unknown' (kept)
A13: IMO = 0 (placeholder) | B13: 0 | C13: set to missing
... A23: Clean rows kept | B23: 8881 | C23: -
A26: field | B26: pct_complete | C26: ships
A27: Ship name | B27: 99.4 | C27: 6833
A28: Flag state | B28: 99.9 | C28: 6869
A29: Vessel type | B29: 96.8 | C29: 6656
A30: IMO number | B30: 26.5 | C30: 1823
A31: IMO passes checksum | B31: 25.5 | C31: 1757
A32: Call sign | B32: 96.1 | C32: 6611
A33: Length | B33: 95.2 | C33: 6546
A34: Speed | B34: 99.8 | C34: 6862
A35: Destination usable (not blank/placeholder) | B35: 79 | C35: 5434
A36: Destination resolved to a port | B36: 35.7 | C36: 2454

Sheet Assumptions
A1: Assumptions (blue = input you can change; yellow = key assumption)
A2: All values are published figures or clearly marked analyst assumptions. Nothing here is measured from AIS.
A4: parameter | B4: size_class | C4: low | D4: central | E4: high | F4: unit | G4: source | H4: note
A5: fuel_at_anchor_t_per_day | B5: small (<100 m) | C5: 0.3 | D5: 0.8 | E5: 2 | F5: tonnes/day/ship | G5: Analyst assumption: no published at-anchor figure by ship size exists. Bracketed by: auxiliary-engine use of 0.5-1 t/day for 40-70k DWT tramp ships (Journal of Shipping and Trade, doi 10.1186/s41072-021-00097-z and 10.1186/s41072-017-0021-y); about 4 t/day auxiliary for a large container ship at sea (maritimepage.com/fuel-consumption-how-much-fuel-cargo-ship-use); 9.4 t/day in port including cargo operations for a 19k DWT tanker (doi 10.1186/s41072-018-0031-4). | H5: Ships at anchor run auxiliary engines and boilers only; replace with company data if available. Unknown size uses the medium-class values.
A6: fuel_at_anchor_t_per_day | B6: medium (100-200 m) | C6: 1 | D6: 2.5 | E6: 5 | F6: tonnes/day/ship | G6: Analyst assumption: no published at-anchor figure by ship size exists. Bracketed by: auxiliary-engine use of 0.5-1 t/day for 40-70k DWT tramp ships (Journal of Shipping and Trade, doi 10.1186/s41072-021-00097-z and 10.1186/s41072-017-0021-y); about 4 t/day auxiliary for a large container ship at sea (maritimepage.com/fuel-consumption-how-much-fuel-cargo-ship-use); 9.4 t/day in port including cargo operations for a 19k DWT tanker (doi 10.1186/s41072-018-0031-4). | H6: Ships at anchor run auxiliary engines and boilers only; replace with company data if available. Unknown size uses the medium-class values.
A7: fuel_at_anchor_t_per_day | B7: large (200-300 m) | C7: 2 | D7: 4 | E7: 9 | F7: tonnes/day/ship | G7: Analyst assumption: no published at-anchor figure by ship size exists. Bracketed by: auxiliary-engine use of 0.5-1 t/day for 40-70k DWT tramp ships (Journal of Shipping and Trade, doi 10.1186/s41072-021-00097-z and 10.1186/s41072-017-0021-y); about 4 t/day auxiliary for a large container ship at sea (maritimepage.com/fuel-consumption-how-much-fuel-cargo-ship-use); 9.4 t/day in port including cargo operations for a 19k DWT tanker (doi 10.1186/s41072-018-0031-4). | H7: Ships at anchor run auxiliary engines and boilers only; replace with company data if available. Unknown size uses the medium-class values.
A8: fuel_at_anchor_t_per_day | B8: very large (>300 m) | C8: 3 | D8: 6 | E8: 12 | F8: tonnes/day/ship | G8: Analyst assumption: no published at-anchor figure by ship size exists. Bracketed by: auxiliary-engine use of 0.5-1 t/day for 40-70k DWT tramp ships (Journal of Shipping and Trade, doi 10.1186/s41072-021-00097-z and 10.1186/s41072-017-0021-y); about 4 t/day auxiliary for a large container ship at sea (maritimepage.com/fuel-consumption-how-much-fuel-cargo-ship-use); 9.4 t/day in port including cargo operations for a 19k DWT tanker (doi 10.1186/s41072-018-0031-4). | H8: Ships at anchor run auxiliary engines and boilers only; replace with company data if available. Unknown size uses the medium-class values.
A9: fuel_at_anchor_t_per_day | B9: unknown size | C9: 1 | D9: 2.5 | E9: 5 | F9: tonnes/day/ship | G9: Analyst assumption: no published at-anchor figure by ship size exists. Bracketed by: auxiliary-engine use of 0.5-1 t/day for 40-70k DWT tramp ships (Journal of Shipping and Trade, doi 10.1186/s41072-021-00097-z and 10.1186/s41072-017-0021-y); about 4 t/day auxiliary for a large container ship at sea (maritimepage.com/fuel-consumption-how-much-fuel-cargo-ship-use); 9.4 t/day in port including cargo operations for a 19k DWT tanker (doi 10.1186/s41072-018-0031-4). | H9: Ships at anchor run auxiliary engines and boilers only; replace with company data if available. Unknown size uses the medium-class values.
A10: fuel_price_usd_per_t | B10: all | C10: 880 | D10: 1328 | E10: 1500 | F10: USD/tonne | G10: Ship & Bunker 6 Oct 2026: 20-port average VLSFO $876.50/mt and MGO $1,500/mt (via shipuniverse.com/?p=22139); Rotterdam conventional LSMGO about $1,328/mt, derived from ENGINE 2 Oct 2026 (B30-LSMGO $1,398 less a $70 premium). | H10: The North Sea and English Channel are a 0.10% sulphur Emission Control Area, so MGO-type fuel is the central case; low is the VLSFO benchmark.
A11: co2_t_per_t_fuel | B11: all | C11: 3.114 | D11: 3.206 | E11: 3.206 | F11: t CO2 per t fuel | G11: EU Regulation 2015/757 as amended by Delegated Regulation 2016/2071: HFO 3.114, LFO 3.151, MGO 3.206 t CO2 per t fuel (legislation.gov.uk/eur/2016/2071). | H11: Tank-to-wake CO2 only; methane and N2O not included.
A12: vessel_opex_usd_per_day | B12: all | C12: 5000 | D12: 7474 | E12: 10000 | F12: USD/day/ship | G12: Low: running cost of $5,000/day in the tramp-ship tables (doi 10.1186/s41072-017-0021-y). Central: Drewry average daily operating cost across 47 ship types and sizes, $7,474 in 2022 (marinelog.com). High: analyst assumption for larger or more complex ships. | H12: Owner running cost (crew, insurance, maintenance). Excludes fuel and charter hire, so cost of delay is conservative.

Sheet Estimates
A1: ESTIMATE: daily fuel, CO2 and cost of ships waiting at anchor near a hub
A2: These are estimates built from the Assumptions sheet, not measurements. Low uses every low assumption together, high every high one, so the range is wide on purpose.
A4: Size class | B4: Ships waiting | C4: Fuel t/day low | D4: Fuel t/day central | E4: Fuel t/day high | F4: CO2 t/day low | G4: CO2 t/day central | H4: CO2 t/day high | I4: Cost USD/day low | J4: Cost USD/day central | K4: Cost USD/day high
A5: small (<100 m) | B5: =COUNTIFS(Clean_Data!$K:$K,"at_anchor",Clean_Data!$AC:$AC,"<>",Clean_Data!$AB:$AB,$A5) | C5: =$B5*Assumptions!$C$5 | D5: =$B5*Assumptions!$D$5 | E5: =$B5*Assumptions!$E$5 | F5: =C5*Assumptions!$C$11 | G5: =D5*Assumptions!$D$11 | H5: =E5*Assumptions!$E$11 | I5: =$B5*(Assumptions!$C$12+Assumptions!$C$5*Assumptions!$C$10) | J5: =$B5*(Assumptions!$D$12+Assumptions!$D$5*Assumptions!$D$10) | K5: =$B5*(Assumptions!$E$12+Assumptions!$E$5*Assumptions!$E$10)
A6: medium (100-200 m) | B6: =COUNTIFS(Clean_Data!$K:$K,"at_anchor",Clean_Data!$AC:$AC,"<>",Clean_Data!$AB:$AB,$A6) | C6: =$B6*Assumptions!$C$6 | D6: =$B6*Assumptions!$D$6 | E6: =$B6*Assumptions!$E$6 | F6: =C6*Assumptions!$C$11 | G6: =D6*Assumptions!$D$11 | H6: =E6*Assumptions!$E$11 | I6: =$B6*(Assumptions!$C$12+Assumptions!$C$6*Assumptions!$C$10) | J6: =$B6*(Assumptions!$D$12+Assumptions!$D$6*Assumptions!$D$10) | K6: =$B6*(Assumptions!$E$12+Assumptions!$E$6*Assumptions!$E$10)
A7: large (200-300 m) | B7: =COUNTIFS(Clean_Data!$K:$K,"at_anchor",Clean_Data!$AC:$AC,"<>",Clean_Data!$AB:$AB,$A7) | C7: =$B7*Assumptions!$C$7 | D7: =$B7*Assumptions!$D$7 | E7: =$B7*Assumptions!$E$7 | F7: =C7*Assumptions!$C$11 | G7: =D7*Assumptions!$D$11 | H7: =E7*Assumptions!$E$11 | I7: =$B7*(Assumptions!$C$12+Assumptions!$C$7*Assumptions!$C$10) | J7: =$B7*(Assumptions!$D$12+Assumptions!$D$7*Assumptions!$D$10) | K7: =$B7*(Assumptions!$E$12+Assumptions!$E$7*Assumptions!$E$10)
A8: very large (>300 m) | B8: =COUNTIFS(Clean_Data!$K:$K,"at_anchor",Clean_Data!$AC:$AC,"<>",Clean_Data!$AB:$AB,$A8) | C8: =$B8*Assumptions!$C$8 | D8: =$B8*Assumptions!$D$8 | E8: =$B8*Assumptions!$E$8 | F8: =C8*Assumptions!$C$11 | G8: =D8*Assumptions!$D$11 | H8: =E8*Assumptions!$E$11 | I8: =$B8*(Assumptions!$C$12+Assumptions!$C$8*Assumptions!$C$10) | J8: =$B8*(Assumptions!$D$12+Assumptions!$D$8*Assumptions!$D$10) | K8: =$B8*(Assumptions!$E$12+Assumptions!$E$8*Assumptions!$E$10)
A9: unknown size | B9: =COUNTIFS(Clean_Data!$K:$K,"at_anchor",Clean_Data!$AC:$AC,"<>",Clean_Data!$AB:$AB,$A9) | C9: =$B9*Assumptions!$C$9 | D9: =$B9*Assumptions!$D$9 | E9: =$B9*Assumptions!$E$9 | F9: =C9*Assumptions!$C$11 | G9: =D9*Assumptions!$D$11 | H9: =E9*Assumptions!$E$11 | I9: =$B9*(Assumptions!$C$12+Assumptions!$C$9*Assumptions!$C$10) | J9: =$B9*(Assumptions!$D$12+Assumptions!$D$9*Assumptions!$D$10) | K9: =$B9*(Assumptions!$E$12+Assumptions!$E$9*Assumptions!$E$10)
A10: Total | B10: =SUM(B5:B9) | C10: =SUM(C5:C9) | D10: =SUM(D5:D9) | E10: =SUM(E5:E9) | F10: =SUM(F5:F9) | G10: =SUM(G5:G9) | H10: =SUM(H5:H9) | I10: =SUM(I5:I9) | ... K10: =SUM(K5:K9)
A12: How to read: cost = ships x (vessel running cost per day + fuel per day x fuel price). Fuel = ships x fuel at anchor per day. CO2 = fuel x emission factor.
A13: This is the cost of ships sitting at anchor near a hub on a typical day. It is an upper bound for congestion-attributable cost, because some waiting is normal.
A14: A real congestion cost needs a baseline of normal waiting (see the time analysis once the history collector has run for several weeks).
A15: AIS contains no operator, cargo or schedule data, so no company-level loss can be computed.

Sheet Clean_Data
A1: mmsi | B1: name | C1: flag | D1: vessel_type | E1: imo | F1: imo_valid | G1: call_sign | H1: lat | I1: lng | J1: status | K1: status_group | L1: speed | M1: heading | N1: minutes_since_update | O1: is_stale | P1: is_dark_flagged | Q1: destination | R1: dest_clean | S1: dest_quality | T1: dest_hub | U1: dest_resolved | V1: destination_port | W1: eta | X1: departure_port | Y1: departure_time | Z1: length_m | AA1: beam_m | AB1: size_class | AC1: hub | AD1: zone | AE1: region | AF1: dist_to_hub_km | AG1: is_edge | AH1: stationary_but_moving | AI1: moving_but_anchored
A2: 246344000 | B2: VB COURAGE | C2: Netherlands | D2: tug | E2: 9963891 | F2: 1 | G2: PHZY | H2: 51.91664 | I2: 4.21994 | J2: moving | K2: moving | L2: 6.1 | M2: 146.7 | N2: 0 | O2: 0 | P2: 0 | Q2: HARBOR TOWAGE | R2: HARBOR TOWAGE | S2: other_text | Z2: 28 | AA2: 13 | AB2: small (<100 m) | AC2: Rotterdam | AD2: Benelux coast | AE2: North Sea & English Channel | AF2: 9.021096 | AG2: 0 | AH2: 0 | AI2: 0
A3: 244060223 | B3: THREE POINT 4 | C3: Netherlands | D3: pleasure | F3: 0 | G3: PC6003 | H3: 51.82074 | I3: 4.04951 | J3: anchored-sea | K3: at_anchor | L3: 0 | N3: 0 | O3: 0 | P3: 0 | S3: missing | Z3: 26 | AA3: 7 | AB3: small (<100 m) | AC3: Rotterdam | AD3: Benelux coast | AE3: North Sea & English Channel | AF3: 14.784914 | AG3: 0 | AH3: 0 | AI3: 0
A4: 244770296 | B4: FOSTA | C4: Netherlands | D4: pleasure | F4: 0 | G4: PH7186 | H4: 53.18726 | I4: 7.20234 | J4: anchored-sea | K4: at_anchor | L4: 0 | M4: 0 | N4: 0 | O4: 0 | P4: 0 | S4: missing | W4: 01-01 00:00 UTC | Z4: 23 | AA4: 5 | AB4: small (<100 m) | AE4: North Sea & English Channel | AG4: 0 | AH4: 0 | AI4: 0
A5: 244740200 | B5: MAAIKE | C5: Netherlands | D5: tanker | F5: 0 | G5: PC2246 | H5: 51.91265 | I5: 4.41838 | J5: moving | K5: idle | L5: 0 | M5: 0 | N5: 0 | O5: 0 | P5: 0 | S5: missing | W5: 05-05 16:28 UTC | Z5: 57 | AA5: 12 | AB5: small (<100 m) | AC5: Rotterdam | AD5: Benelux coast | AE5: North Sea & English Channel | AF5: 22.220796 | AG5: 0 | AH5: 1 | AI5: 0
A6: 230196150 | B6: TARMO | C6: Finland | D6: pleasure | F6: 0 | G6: OHA7234 | H6: 51.55138 | I6: 3.81298 | J6: moving | K6: idle | L6: 0 | N6: 0 | O6: 0 | P6: 0 | Q6: DORDRECHT | R6: DORDRECHT | S6: other_text | U6: DORDRECHT | V6: DORDRECHT | W6: 04-03 12:30 UTC | Z6: 20 | AA6: 5 | AB6: small (<100 m) | AE6: North Sea & English Channel | AG6: 0 | AH6: 1 | AI6: 0
A7: 246327000 | B7: HD35 NOORDERLICHT | C7: Netherlands | D7: fishing | E7: 9115963 | F7: 1 | G7: PDPH | H7: 52.95074 | I7: 4.78561 | J7: moving | K7: idle | L7: 0 | N7: 0 | O7: 0 | P7: 0 | Q7: SEA | R7: SEA | S7: other_text | U7: EDINBURGH OF THE SEVEN SEAS | V7: EDINBURGH OF THE SEVEN SEAS | W7: 01-19 00:00 UTC | Z7: 24 | AA7: 6 | AB7: small (<100 m) | AE7: North Sea & English Channel | AG7: 0 | AH7: 1 | AI7: 0
A8: 244700469 | B8: CARLIJN | C8: Netherlands | D8: cargo | F8: 0 | G8: PE8492 | H8: 52.48828 | I8: 5.33218 | J8: moving | K8: moving | L8: 6.1 | M8: 57 | N8: 0 | O8: 0 | P8: 0 | Q8: ZWARTE WATER | R8: ZWARTE WATER | S8: other_text | W8: 10-11 19:29 UTC | X8: ZAANDAM | Y8: 2026-10-11T05:55:25.285242+00:00 | Z8: 86 | AA8: 11 | AB8: small (<100 m) | AE8: North Sea & English Channel | AG8: 0 | AH8: 0 | AI8: 0
A9: 244084000 | B9: TENDER I | C9: Netherlands | D9: other | E9: 8134039 | F9: 1 | G9: PHXT | H9: 52.46451 | I9: 4.59495 | J9: anchored-sea | K9: at_anchor | L9: 0.1 | M9: 192.1 | N9: 0 | O9: 0 | P9: 0 | S9: missing | Z9: 41 | AA9: 7 | AB9: small (<100 m) | AC9: IJmuiden | AD9: Benelux coast | AE9: North Sea & English Channel | AF9: 1.1302051 | AG9: 0 | AH9: 0 | AI9: 0
A10: 244660833 | B10: VRIENDSCHAP | C10: Netherlands | D10: pleasure | F10: 0 | G10: PH3173 | H10: 52.45979 | I10: 5.03875 | J10: anchored-sea | K10: at_anchor | L10: 0 | M10: 302.2 | N10: 0 | O10: 0 | P10: 0 | Q10: MONNICKENDAM | R10: MONNICKENDAM | S10: other_text | Z10: 32 | AA10: 6 | AB10: small (<100 m) | AE10: North Sea & English Channel | AG10: 0 | AH10: 0 | AI10: 0
A11: 244078768 | B11: HILDA S | C11: Netherlands | D11: tanker | F11: 0 | G11: PF6761 | H11: 51.8207 | I11: 4.69163 | J11: moving | K11: idle | L11: 0.1 | M11: 113.4 | N11: 0 | O11: 0 | P11: 0 | S11: missing | Z11: 35 | AA11: 7 | AB11: small (<100 m) | AE11: North Sea & English Channel | AG11: 0 | AH11: 1 | AI11: 0
A12: 235005350 | B12: QUO VADIS | C12: United Kingdom | D12: fishing | E12: 9101223 | F12: 1 | G12: VQHP9 | H12: 53.17938 | I12: 5.41462 | J12: moving | K12: idle | L12: 0 | M12: 251.8 | N12: 0 | O12: 0 | P12: 0 | Q12: FISHGROUNDS | R12: FISHGROUNDS | S12: other_text | Z12: 43 | AA12: 8 | AB12: small (<100 m) | AE12: North Sea & English Channel | AG12: 0 | AH12: 1 | AI12: 0
A13: 244660659 | B13: AEGIR | C13: Netherlands | D13: other | F13: 0 | G13: PD2303 | H13: 53.0505 | I13: 5.39918 | J13: moving | K13: idle | L13: 0 | N13: 0 | O13: 0 | P13: 0 | Q13: MAKKUM | R13: MAKKUM | S13: other_text | W13: 04-16 14:00 UTC | Z13: 20 | AA13: 6 | AB13: small (<100 m) | AE13: North Sea & English Channel | AG13: 0 | AH13: 1 | AI13: 0
A14: 269057062 | B14: KINGSTON | C14: Switzerland | D14: tanker | F14: 0 | G14: HE7062 | H14: 52.02164 | I14: 5.11416 | J14: moving | K14: moving | L14: 0.9 | M14: 195.8 | N14: 0 | O14: 0 | P14: 0 | Q14: ATM MOERDIJK | R14: ATM MOERDIJK | S14: other_text | W14: 10-11 12:23 UTC | X14: ZAANDAM | Y14: 2026-10-11T05:54:17.441638+00:00 | Z14: 86 | AA14: 10 | AB14: small (<100 m) | AE14: North Sea & English Channel | AG14: 0 | AH14: 0 | AI14: 0
A15: 244770588 | B15: PIETERNELLA | C15: Netherlands | D15: cargo | F15: 0 | G15: PE6551 | H15: 51.97223 | I15: 5.30563 | J15: moving | K15: idle | L15: 0 | M15: 230.7 | N15: 0 | O15: 0 | P15: 0 | Q15: URK | R15: URK | S15: other_text | U15: GRAND TURK | V15: GRAND TURK | W15: 07-23 00:00 UTC | Z15: 75 | AA15: 8 | AB15: small (<100 m) | AE15: North Sea & English Channel | AG15: 0 | AH15: 1 | AI15: 0
A16: 244870902 | B16: EQUILIBRE | C16: Netherlands | D16: pleasure | F16: 0 | G16: PB3774 | H16: 51.22882 | I16: 4.40612 | J16: moving | K16: idle | L16: 0 | N16: 0 | O16: 0 | P16: 0 | Q16: ANTWERPEN | R16: ANTWERPEN | S16: hub_name | T16: Antwerp | U16: Antwerp | V16: ANTWERPEN | Z16: 21 | AA16: 6 | AB16: small (<100 m) | AC16: Antwerp | AD16: Benelux coast | AE16: North Sea & English Channel | AF16: 7.002575 | AG16: 0 | AH16: 1 | AI16: 0
A17: 205375690 | B17: ACALI | C17: Belgium | D17: cargo | F17: 0 | G17: OT3756 | H17: 51.23907 | I17: 4.46932 | J17: anchored-sea | K17: at_anchor | L17: 0 | N17: 0 | O17: 0 | P17: 0 | Q17: ANTWERPEN PSA ANTWE | R17: ANTWERPEN PSA ANTWE | S17: hub_name | T17: Antwerp | U17: Antwerp | V17: ANTWERPEN | W17: 10-02 04:06 UTC | Z17: 196 | AA17: 12 | AB17: medium (100-200 m) | AC17: Antwerp | AD17: Benelux coast | AE17: North Sea & English Channel | AF17: 10.287582 | AG17: 0 | AH17: 0 | AI17: 0
A18: 244010025 | B18: PIET HEIN | C18: Netherlands | D18: passenger | F18: 0 | G18: PD2717 | H18: 51.90869 | I18: 4.48231 | J18: moving | K18: idle | L18: 0.1 | M18: 357.4 | N18: 0 | O18: 0 | P18: 0 | Q18: ROTTERDAM | R18: ROTTERDAM | S18: hub_name | T18: Rotterdam | U18: Rotterdam | V18: ROTTERDAM | W18: 01-31 21:00 UTC | Z18: 38 | AA18: 10 | AB18: small (<100 m) | AC18: Rotterdam | AD18: Benelux coast | AE18: North Sea & English Channel | AF18: 26.613054 | AG18: 0 | AH18: 1 | AI18: 0
A19: 244670420 | B19: HOOP DOET LEVEN | C19: Netherlands | D19: passenger | F19: 0 | G19: PC2473 | H19: 52.87989 | I19: 5.36687 | J19: anchored-sea | K19: at_anchor | L19: 0 | M19: 249.2 | N19: 0 | O19: 0 | P19: 0 | Q19: LEEUWARDEN | R19: LEEUWARDEN | S19: other_text | W19: 04-16 15:10 UTC | Z19: 28 | AA19: 5 | AB19: small (<100 m) | AE19: North Sea & English Channel | AG19: 0 | AH19: 0 | AI19: 0
A20: 244830939 | B20: ZK9 ANTONIA | C20: Netherlands | D20: fishing | F20: 0 | G20: PA6790 | H20: 53.40793 | I20: 6.20022 | J20: moving | K20: idle | L20: 0 | N20: 0 | O20: 0 | P20: 0 | Q20: LAUWERSOOG | R20: LAUWERSOOG | S20: other_text | W20: 08-09 12:45 UTC | Z20: 19 | AA20: 5 | AB20: small (<100 m) | AE20: North Sea & English Channel | AG20: 0 | AH20: 1 | AI20: 0
A21: 245617000 | B21: OD3 ADRIANNE | C21: Netherlands | D21: fishing | E21: 8008371 | F21: 1 | G21: PFWH | H21: 51.82532 | I21: 4.03332 | J21: moving | K21: idle | L21: 0.1 | M21: 307.8 | N21: 0 | O21: 0 | P21: 0 | Q21: STELLENDAM | R21: STELLENDAM | S21: other_text | Z21: 24 | AA21: 6 | AB21: small (<100 m) | AC21: Rotterdam | AD21: Benelux coast | AE21: North Sea & English Channel | AF21: 14.59956 | AG21: 0 | AH21: 1 | AI21: 0
A22: 244376506 | B22: NZK PONT 103 | C22: Netherlands | D22: passenger | F22: 0 | G22: PE5688 | H22: 52.46292 | I22: 4.63222 | J22: anchored-port | K22: at_berth | L22: 0 | N22: 0 | O22: 0 | P22: 0 | Q22: VELSEN8NZ | R22: VELSEN8NZ | S22: other_text | W22: 06-02 00:51 UTC | X22: IJMUIDEN | Y22: 2026-10-11T08:14:09.343383+00:00 | Z22: 42 | AA22: 15 | AB22: small (<100 m) | AC22: IJmuiden | AD22: Benelux coast | AE22: North Sea & English Channel | AF22: 3.552804 | AG22: 0 | AH22: 0 | AI22: 0
A23: 244730446 | B23: LEANDER | C23: Netherlands | D23: other | F23: 0 | G23: PB9533 | H23: 51.23943 | I23: 4.41852 | J23: anchored-sea | K23: at_anchor | L23: 0 | N23: 0 | O23: 0 | P23: 0 | S23: missing | Z23: 13 | AA23: 5 | AB23: small (<100 m) | AC23: Antwerp | AD23: Benelux coast | AE23: North Sea & English Channel | AF23: 7.0359359 | AG23: 0 | AH23: 0 | AI23: 0
A24: 256002474 | B24: BARBAROSSA I | C24: Malta | D24: other | F24: 0 | G24: 9HA5570 | H24: 53.33266 | I24: 6.93458 | J24: anchored-sea | K24: at_anchor | L24: 0 | N24: 0 | O24: 0 | P24: 0 | Q24: NORDERNEY | R24: NORDERNEY | S24: other_text | W24: 08-13 08:30 UTC | Z24: 68 | AA24: 30 | AB24: small (<100 m) | AC24: Eemshaven | AD24: German Bight & Ems | AE24: North Sea & English Channel | AF24: 14.476687 | AG24: 0 | AH24: 0 | AI24: 0
A25: 244704000 | B25: UK225 AUKE SENIOR | C25: Netherlands | D25: fishing | E25: 9856517 | F25: 1 | G25: PCWI | H25: 53.4562 | I25: 6.82485 | J25: moving | K25: idle | L25: 0 | M25: 276 | N25: 0 | O25: 0 | P25: 0 | Q25: EEMSHAVEN | R25: EEMSHAVEN | S25: hub_name | T25: Eemshaven | U25: Eemshaven | V25: EEMSHAVEN | Z25: 30 | AA25: 9 | AB25: small (<100 m) | AC25: Eemshaven | AD25: German Bight & Ems | AE25: North Sea & English Channel | AF25: 1.2172079 | AG25: 0 | AH25: 1 | AI25: 0
A26: 244740568 | B26: LINQUENDA-II | C26: Netherlands | D26: passenger | F26: 0 | G26: @WV304 | H26: 51.82103 | I26: 4.12859 | J26: anchored-sea | K26: at_anchor | L26: 0 | N26: 0 | O26: 0 | P26: 0 | Q26: HELLEVOETSLUIS | R26: HELLEVOETSLUIS | S26: other_text | W26: 10-15 16:00 UTC | Z26: 25 | AA26: 6 | AB26: small (<100 m) | AC26: Rotterdam | AD26: Benelux coast | AE26: North Sea & English Channel | AF26: 14.474451 | AG26: 0 | AH26: 0 | AI26: 0
A27: 244210287 | B27: JACKSON 2 | C27: Netherlands | D27: passenger | F27: 0 | G27: PF4419 | H27: 52.38563 | I27: 4.89051 | J27: anchored-sea | K27: at_anchor | L27: 0 | N27: 0 | O27: 0 | P27: 0 | S27: missing | Z27: 7 | AA27: 4 | AB27: small (<100 m) | AC27: Amsterdam | AD27: Benelux coast | AE27: North Sea & English Channel | AF27: 5.0443055 | AG27: 0 | AH27: 0 | AI27: 0
A28: 244660628 | B28: MI-ARENA | C28: Netherlands | D28: other | F28: 0 | G28: PE6969 | H28: 51.3217 | I28: 3.82053 | J28: moving | K28: idle | L28: 0 | N28: 0 | O28: 0 | P28: 0 | S28: missing | Z28: 80 | AA28: 9 | AB28: small (<100 m) | AC28: Terneuzen | AD28: Benelux coast | AE28: North Sea & English Channel | AF28: 1.1334773 | AG28: 0 | AH28: 1 | AI28: 0
A29: 244020020 | B29: BLACK BETTY | C29: Netherlands | D29: passenger | F29: 0 | G29: PA3107 | H29: 53.17576 | I29: 5.41295 | J29: anchored-sea | K29: at_anchor | L29: 0 | N29: 0 | O29: 0 | P29: 0 | S29: missing | Z29: 25 | AA29: 6 | AB29: small (<100 m) | AE29: North Sea & English Channel | AG29: 0 | AH29: 0 | AI29: 0
A30: 244710927 | B30: JEANNET | C30: Netherlands | D30: cargo | F30: 0 | G30: PH3275 | H30: 51.69748 | I30: 4.41974 | J30: anchored-sea | K30: at_anchor | L30: 0 | N30: 0 | O30: 0 | P30: 0 | Q30: GAVERE BOVENSCHELDE | R30: GAVERE BOVENSCHELDE | S30: other_text | W30: 10-10 06:17 UTC | Z30: 85 | AA30: 9 | AB30: small (<100 m) | AE30: North Sea & English Channel | AG30: 0 | AH30: 0 | AI30: 0
A31: 246840000 | B31: KG-8 ENSIS | C31: Netherlands | D31: fishing | E31: 9958248 | F31: 1 | G31: PFTF | H31: 51.61672 | I31: 3.68968 | J31: moving | K31: idle | L31: 0 | M31: 116.4 | N31: 0 | O31: 0 | P31: 0 | Q31: FISHING GROUNDS | R31: FISHING GROUNDS | S31: other_text | Z31: 25 | AA31: 8 | AB31: small (<100 m) | AE31: North Sea & English Channel | AG31: 0 | AH31: 1 | AI31: 0
A32: 244710579 | B32: BRAM | C32: Netherlands | D32: tug | F32: 0 | G32: PI9166 | H32: 52.42033 | I32: 4.84602 | J32: moving | K32: idle | L32: 0 | M32: 278.8 | N32: 0 | O32: 0 | P32: 0 | Q32: THUISHAVEN | R32: THUISHAVEN | S32: other_text | Z32: 23 | AA32: 6 | AB32: small (<100 m) | AC32: Amsterdam | AD32: Benelux coast | AE32: North Sea & English Channel | AF32: 2.8679697 | AG32: 0 | AH32: 1 | AI32: 0
A33: 244110350 | B33: LA REINE | C33: Netherlands | D33: passenger | F33: 0 | G33: PE9619 | H33: 52.36003 | I33: 4.90478 | J33: moving | K33: idle | L33: 0.1 | N33: 0 | O33: 0 | P33: 0 | Q33: AMSTERDAM | R33: AMSTERDAM | S33: hub_name | T33: Amsterdam | U33: Amsterdam | V33: AMSTERDAM | Z33: 12 | AA33: 3 | AB33: small (<100 m) | AC33: Amsterdam | AD33: Benelux coast | AE33: North Sea & English Channel | AF33: 7.27102 | AG33: 0 | AH33: 1 | AI33: 0
A34: 244660069 | B34: LEGACY | C34: Netherlands | D34: cargo | F34: 0 | G34: PE9657 | H34: 51.90285 | I34: 5.54278 | J34: anchored-sea | K34: at_anchor | L34: 1.2 | M34: 78.5 | N34: 0 | O34: 0 | P34: 0 | Q34: HAFEN SCHWELGERN | R34: HAFEN SCHWELGERN | S34: other_text | W34: 10-11 08:18 UTC | Z34: 135 | AA34: 12 | AB34: medium (100-200 m) | AE34: North Sea & English Channel | AG34: 0 | AH34: 0 | AI34: 0
A35: 245217000 | B35: SVITZER JUPITER | C35: Netherlands | D35: tug | E35: 9878254 | F35: 1 | G35: PDSK | H35: 52.46144 | I35: 4.58792 | J35: moving | K35: idle | L35: 0.1 | M35: 59.4 | N35: 0 | O35: 0 | P35: 0 | Q35: IJMUIDEN/AMSTERDAM | R35: IJMUIDEN/AMSTERDAM | S35: hub_name | T35: Amsterdam | U35: Amsterdam | V35: AMSTERDAM | W35: 09-18 12:00 UTC | Z35: 23 | AA35: 12 | AB35: small (<100 m) | AC35: IJmuiden | AD35: Benelux coast | AE35: North Sea & English Channel | AF35: 0.55997462 | AG35: 0 | AH35: 1 | AI35: 0
A36: 244780112 | B36: BOTA FOGO | C36: Netherlands | D36: passenger | F36: 0 | G36: PF7734 | H36: 52.36977 | I36: 4.93734 | J36: moving | K36: idle | L36: 0 | N36: 0 | O36: 0 | P36: 0 | Q36: AMSTERDAM | R36: AMSTERDAM | S36: hub_name | T36: Amsterdam | U36: Amsterdam | V36: AMSTERDAM | Z36: 20 | AA36: 4 | AB36: small (<100 m) | AC36: Amsterdam | AD36: Benelux coast | AE36: North Sea & English Channel | AF36: 8.6440326 | AG36: 0 | AH36: 1 | AI36: 0
A37: 244013532 | B37: BRUUZER | C37: Netherlands | D37: passenger | F37: 0 | G37: PF6647 | H37: 53.04009 | I37: 4.84975 | J37: moving | K37: idle | L37: 0 | N37: 0 | O37: 0 | P37: 0 | Q37: OUDESCHILD | R37: OUDESCHILD | S37: other_text | W37: 04-15 04:30 UTC | Z37: 13 | AA37: 5 | AB37: small (<100 m) | AE37: North Sea & English Channel | AG37: 0 | AH37: 1 | AI37: 0
A38: 235053185 | B38: STAR CLIPPER | C38: United Kingdom | D38: other | F38: 0 | G38: MCJP5 | H38: 51.50744 | I38: 0.00684 | J38: moving | K38: idle | L38: 0 | M38: 46 | N38: 0 | O38: 0 | P38: 0 | Q38: DT#U@A49AFP@6/ E@P | R38: DT#U@A49AFP@6/ E@P | S38: other_text | AB38: unknown size | AE38: North Sea & English Channel | AG38: 0 | AH38: 1 | AI38: 0
A39: 244020365 | B39: NICKELINE | C39: Netherlands | D39: pleasure | F39: 0 | G39: PH2640 | H39: 51.92145 | I39: 4.49956 | J39: moving | K39: idle | L39: 0 | N39: 0 | O39: 0 | P39: 0 | Q39: ? | R39: ? | S39: junk | Z39: 26 | AA39: 6 | AB39: small (<100 m) | AC39: Rotterdam | AD39: Benelux coast | AE39: North Sea & English Channel | AF39: 27.575857 | AG39: 0 | AH39: 1 | AI39: 0
A40: 244750085 | B40: POOLSTER | C40: Netherlands | D40: passenger | F40: 0 | G40: PF7996 | H40: 53.17494 | I40: 5.41095 | J40: anchored-sea | K40: at_anchor | L40: 0 | M40: 219 | N40: 0 | O40: 0 | P40: 0 | S40: missing | Z40: 36 | AA40: 6 | AB40: small (<100 m) | AE40: North Sea & English Channel | AG40: 0 | AH40: 0 | AI40: 0
...
